[2024-05-06T00:03:11.057+0000] {processor.py:161} INFO - Started process (PID=10374) to work on /home/airflow/.local/lib/python3.12/site-packages/airflow/example_dags/example_xcom.py
[2024-05-06T00:03:11.219+0000] {processor.py:830} INFO - Processing file /home/airflow/.local/lib/python3.12/site-packages/airflow/example_dags/example_xcom.py for tasks to queue
[2024-05-06T00:03:11.531+0000] {logging_mixin.py:188} INFO - [2024-05-06T00:03:11.365+0000] {dagbag.py:540} INFO - Filling up the DagBag from /home/airflow/.local/lib/python3.12/site-packages/airflow/example_dags/example_xcom.py
[2024-05-06T00:03:22.307+0000] {processor.py:840} INFO - DAG(s) 'example_xcom' retrieved from /home/airflow/.local/lib/python3.12/site-packages/airflow/example_dags/example_xcom.py
[2024-05-06T00:30:51.452+0000] {logging_mixin.py:188} INFO - [2024-05-06T00:30:51.446+0000] {dag.py:3096} INFO - Sync 1 DAGs
[2024-05-06T00:36:57.552+0000] {processor.py:161} INFO - Started process (PID=10392) to work on /home/airflow/.local/lib/python3.12/site-packages/airflow/example_dags/example_xcom.py
[2024-05-06T00:36:57.679+0000] {processor.py:830} INFO - Processing file /home/airflow/.local/lib/python3.12/site-packages/airflow/example_dags/example_xcom.py for tasks to queue
[2024-05-06T00:36:57.915+0000] {logging_mixin.py:188} INFO - [2024-05-06T00:36:57.881+0000] {dagbag.py:540} INFO - Filling up the DagBag from /home/airflow/.local/lib/python3.12/site-packages/airflow/example_dags/example_xcom.py
[2024-05-06T00:37:00.350+0000] {processor.py:840} INFO - DAG(s) 'example_xcom' retrieved from /home/airflow/.local/lib/python3.12/site-packages/airflow/example_dags/example_xcom.py
[2024-05-06T00:37:04.680+0000] {logging_mixin.py:188} INFO - [2024-05-06T00:37:04.677+0000] {dag.py:3096} INFO - Sync 1 DAGs
[2024-05-06T00:37:06.008+0000] {logging_mixin.py:188} INFO - [2024-05-06T00:37:05.979+0000] {dag.py:3954} INFO - Setting next_dagrun for example_xcom to 2021-01-01 00:00:00+00:00, run_after=2021-01-01 00:00:00+00:00
[2024-05-06T00:37:06.561+0000] {processor.py:183} INFO - Processing /home/airflow/.local/lib/python3.12/site-packages/airflow/example_dags/example_xcom.py took 10.041 seconds
[2024-05-06T01:35:30.447+0000] {processor.py:161} INFO - Started process (PID=10443) to work on /home/airflow/.local/lib/python3.12/site-packages/airflow/example_dags/example_xcom.py
[2024-05-06T01:35:30.475+0000] {processor.py:830} INFO - Processing file /home/airflow/.local/lib/python3.12/site-packages/airflow/example_dags/example_xcom.py for tasks to queue
[2024-05-06T01:35:30.527+0000] {logging_mixin.py:188} INFO - [2024-05-06T01:35:30.520+0000] {dagbag.py:540} INFO - Filling up the DagBag from /home/airflow/.local/lib/python3.12/site-packages/airflow/example_dags/example_xcom.py
[2024-05-06T01:35:33.486+0000] {processor.py:840} INFO - DAG(s) 'example_xcom' retrieved from /home/airflow/.local/lib/python3.12/site-packages/airflow/example_dags/example_xcom.py
[2024-05-06T01:35:38.341+0000] {logging_mixin.py:188} INFO - [2024-05-06T01:35:38.273+0000] {dag.py:3096} INFO - Sync 1 DAGs
[2024-05-06T01:35:50.709+0000] {logging_mixin.py:188} INFO - [2024-05-06T01:35:47.391+0000] {dag.py:3954} INFO - Setting next_dagrun for example_xcom to 2021-01-01 00:00:00+00:00, run_after=2021-01-01 00:00:00+00:00
[2024-05-06T05:36:57.217+0000] {processor.py:876} ERROR - Error logging import errors!
Traceback (most recent call last):
  File "/home/airflow/.local/lib/python3.12/site-packages/sqlalchemy/engine/base.py", line 3371, in _wrap_pool_connect
    return fn()
           ^^^^
  File "/home/airflow/.local/lib/python3.12/site-packages/sqlalchemy/pool/base.py", line 327, in connect
    return _ConnectionFairy._checkout(self)
           ^^^^^^^^^^^^^^^^^^^^^^^^^^^^^^^^
  File "/home/airflow/.local/lib/python3.12/site-packages/sqlalchemy/pool/base.py", line 894, in _checkout
    fairy = _ConnectionRecord.checkout(pool)
            ^^^^^^^^^^^^^^^^^^^^^^^^^^^^^^^^
  File "/home/airflow/.local/lib/python3.12/site-packages/sqlalchemy/pool/base.py", line 497, in checkout
    with util.safe_reraise():
  File "/home/airflow/.local/lib/python3.12/site-packages/sqlalchemy/util/langhelpers.py", line 70, in __exit__
    compat.raise_(
  File "/home/airflow/.local/lib/python3.12/site-packages/sqlalchemy/util/compat.py", line 211, in raise_
    raise exception
  File "/home/airflow/.local/lib/python3.12/site-packages/sqlalchemy/pool/base.py", line 495, in checkout
    dbapi_connection = rec.get_connection()
                       ^^^^^^^^^^^^^^^^^^^^
  File "/home/airflow/.local/lib/python3.12/site-packages/sqlalchemy/pool/base.py", line 659, in get_connection
    self.__connect()
  File "/home/airflow/.local/lib/python3.12/site-packages/sqlalchemy/pool/base.py", line 690, in __connect
    with util.safe_reraise():
  File "/home/airflow/.local/lib/python3.12/site-packages/sqlalchemy/util/langhelpers.py", line 70, in __exit__
    compat.raise_(
  File "/home/airflow/.local/lib/python3.12/site-packages/sqlalchemy/util/compat.py", line 211, in raise_
    raise exception
  File "/home/airflow/.local/lib/python3.12/site-packages/sqlalchemy/pool/base.py", line 686, in __connect
    self.dbapi_connection = connection = pool._invoke_creator(self)
                                         ^^^^^^^^^^^^^^^^^^^^^^^^^^
  File "/home/airflow/.local/lib/python3.12/site-packages/sqlalchemy/engine/create.py", line 574, in connect
    return dialect.connect(*cargs, **cparams)
           ^^^^^^^^^^^^^^^^^^^^^^^^^^^^^^^^^^
  File "/home/airflow/.local/lib/python3.12/site-packages/sqlalchemy/engine/default.py", line 598, in connect
    return self.dbapi.connect(*cargs, **cparams)
           ^^^^^^^^^^^^^^^^^^^^^^^^^^^^^^^^^^^^^
  File "/home/airflow/.local/lib/python3.12/site-packages/psycopg2/__init__.py", line 122, in connect
    conn = _connect(dsn, connection_factory=connection_factory, **kwasync)
           ^^^^^^^^^^^^^^^^^^^^^^^^^^^^^^^^^^^^^^^^^^^^^^^^^^^^^^^^^^^^^^^
psycopg2.OperationalError: could not translate host name "postgres" to address: Temporary failure in name resolution


The above exception was the direct cause of the following exception:

Traceback (most recent call last):
  File "/home/airflow/.local/lib/python3.12/site-packages/airflow/dag_processing/processor.py", line 869, in process_file
    DagFileProcessor.update_import_errors(
  File "/home/airflow/.local/lib/python3.12/site-packages/airflow/api_internal/internal_api_call.py", line 115, in wrapper
    return func(*args, **kwargs)
           ^^^^^^^^^^^^^^^^^^^^^
  File "/home/airflow/.local/lib/python3.12/site-packages/airflow/utils/session.py", line 76, in wrapper
    return func(*args, **kwargs)
           ^^^^^^^^^^^^^^^^^^^^^
  File "/home/airflow/.local/lib/python3.12/site-packages/airflow/dag_processing/processor.py", line 615, in update_import_errors
    session.execute(
  File "/home/airflow/.local/lib/python3.12/site-packages/sqlalchemy/orm/session.py", line 1716, in execute
    conn = self._connection_for_bind(bind)
           ^^^^^^^^^^^^^^^^^^^^^^^^^^^^^^^
  File "/home/airflow/.local/lib/python3.12/site-packages/sqlalchemy/orm/session.py", line 1555, in _connection_for_bind
    return self._transaction._connection_for_bind(
           ^^^^^^^^^^^^^^^^^^^^^^^^^^^^^^^^^^^^^^^
  File "/home/airflow/.local/lib/python3.12/site-packages/sqlalchemy/orm/session.py", line 750, in _connection_for_bind
    conn = bind.connect()
           ^^^^^^^^^^^^^^
  File "/home/airflow/.local/lib/python3.12/site-packages/sqlalchemy/future/engine.py", line 412, in connect
    return super(Engine, self).connect()
           ^^^^^^^^^^^^^^^^^^^^^^^^^^^^^
  File "/home/airflow/.local/lib/python3.12/site-packages/sqlalchemy/engine/base.py", line 3325, in connect
    return self._connection_cls(self, close_with_result=close_with_result)
           ^^^^^^^^^^^^^^^^^^^^^^^^^^^^^^^^^^^^^^^^^^^^^^^^^^^^^^^^^^^^^^^
  File "/home/airflow/.local/lib/python3.12/site-packages/sqlalchemy/engine/base.py", line 96, in __init__
    else engine.raw_connection()
         ^^^^^^^^^^^^^^^^^^^^^^^
  File "/home/airflow/.local/lib/python3.12/site-packages/sqlalchemy/engine/base.py", line 3404, in raw_connection
    return self._wrap_pool_connect(self.pool.connect, _connection)
           ^^^^^^^^^^^^^^^^^^^^^^^^^^^^^^^^^^^^^^^^^^^^^^^^^^^^^^^
  File "/home/airflow/.local/lib/python3.12/site-packages/sqlalchemy/engine/base.py", line 3374, in _wrap_pool_connect
    Connection._handle_dbapi_exception_noconnection(
  File "/home/airflow/.local/lib/python3.12/site-packages/sqlalchemy/engine/base.py", line 2208, in _handle_dbapi_exception_noconnection
    util.raise_(
  File "/home/airflow/.local/lib/python3.12/site-packages/sqlalchemy/util/compat.py", line 211, in raise_
    raise exception
  File "/home/airflow/.local/lib/python3.12/site-packages/sqlalchemy/engine/base.py", line 3371, in _wrap_pool_connect
    return fn()
           ^^^^
  File "/home/airflow/.local/lib/python3.12/site-packages/sqlalchemy/pool/base.py", line 327, in connect
    return _ConnectionFairy._checkout(self)
           ^^^^^^^^^^^^^^^^^^^^^^^^^^^^^^^^
  File "/home/airflow/.local/lib/python3.12/site-packages/sqlalchemy/pool/base.py", line 894, in _checkout
    fairy = _ConnectionRecord.checkout(pool)
            ^^^^^^^^^^^^^^^^^^^^^^^^^^^^^^^^
  File "/home/airflow/.local/lib/python3.12/site-packages/sqlalchemy/pool/base.py", line 497, in checkout
    with util.safe_reraise():
  File "/home/airflow/.local/lib/python3.12/site-packages/sqlalchemy/util/langhelpers.py", line 70, in __exit__
    compat.raise_(
  File "/home/airflow/.local/lib/python3.12/site-packages/sqlalchemy/util/compat.py", line 211, in raise_
    raise exception
  File "/home/airflow/.local/lib/python3.12/site-packages/sqlalchemy/pool/base.py", line 495, in checkout
    dbapi_connection = rec.get_connection()
                       ^^^^^^^^^^^^^^^^^^^^
  File "/home/airflow/.local/lib/python3.12/site-packages/sqlalchemy/pool/base.py", line 659, in get_connection
    self.__connect()
  File "/home/airflow/.local/lib/python3.12/site-packages/sqlalchemy/pool/base.py", line 690, in __connect
    with util.safe_reraise():
  File "/home/airflow/.local/lib/python3.12/site-packages/sqlalchemy/util/langhelpers.py", line 70, in __exit__
    compat.raise_(
  File "/home/airflow/.local/lib/python3.12/site-packages/sqlalchemy/util/compat.py", line 211, in raise_
    raise exception
  File "/home/airflow/.local/lib/python3.12/site-packages/sqlalchemy/pool/base.py", line 686, in __connect
    self.dbapi_connection = connection = pool._invoke_creator(self)
                                         ^^^^^^^^^^^^^^^^^^^^^^^^^^
  File "/home/airflow/.local/lib/python3.12/site-packages/sqlalchemy/engine/create.py", line 574, in connect
    return dialect.connect(*cargs, **cparams)
           ^^^^^^^^^^^^^^^^^^^^^^^^^^^^^^^^^^
  File "/home/airflow/.local/lib/python3.12/site-packages/sqlalchemy/engine/default.py", line 598, in connect
    return self.dbapi.connect(*cargs, **cparams)
           ^^^^^^^^^^^^^^^^^^^^^^^^^^^^^^^^^^^^^
  File "/home/airflow/.local/lib/python3.12/site-packages/psycopg2/__init__.py", line 122, in connect
    conn = _connect(dsn, connection_factory=connection_factory, **kwasync)
           ^^^^^^^^^^^^^^^^^^^^^^^^^^^^^^^^^^^^^^^^^^^^^^^^^^^^^^^^^^^^^^^
sqlalchemy.exc.OperationalError: (psycopg2.OperationalError) could not translate host name "postgres" to address: Temporary failure in name resolution

(Background on this error at: https://sqlalche.me/e/14/e3q8)
[2024-05-06T05:37:17.650+0000] {processor.py:183} INFO - Processing /home/airflow/.local/lib/python3.12/site-packages/airflow/example_dags/example_xcom.py took 96.846 seconds
